<mujoco model="inverted pendulum">
    <compiler inertiafromgeom="true" />
    <default>
        <joint armature="0" damping="1" limited="true" />
        <geom contype="0" friction="1 0.1 0.1" />
        <tendon />
        <motor ctrlrange="-3 3" />
    </default>
    <option gravity="0 0 -9.81" timestep="0.02" />
    <custom>
        <!-- brax custom params -->
        <numeric data="10000" name="constraint_stiffness" />
        <numeric data="10000" name="constraint_limit_stiffness" />
        <numeric data="0" name="spring_mass_scale" />
        <numeric data="1" name="spring_inertia_scale" />
        <numeric data="5" name="solver_maxls" />
    </custom>
    <size nstack="3000" />
    <worldbody>
        <geom name="rail_y" pos="0 0 0" quat="1.0 0 0.0 0" size="0.02 1" type="capsule" />
        <body name="rail_x_with_cart" pos=" 0 0 0">
            <joint axis="0 0 1" limited="true" name="slider_y" pos="0 0 0" range="-1 1" type="slide" />
            <geom name="rail_x" pos="0 0 0" quat="0.707 0 0.707 0" size="0.02 1" type="capsule" />
            <body name="cart" pos="0 0 0">
                <joint axis="1 0 0" limited="true" name="slider_x" pos="0 0 0" range="-1 1" type="slide" />
                <geom name="cart" pos="0 0 0" quat="0.707 0 0.707 0" size="0.1 0.1" type="capsule" />
                <body name="pole" pos="0 0 0">
                    <joint axis="0 1 0" name="hinge" pos="0 0 0" range="-90 90" type="hinge" />
                    <geom fromto="0 0 0 0.001 0 0.6" name="cpole" size="0.049 0.3" type="capsule" />
                </body>
            </body>
        </body>
    </worldbody>
    <actuator>
        <motor ctrllimited="true" ctrlrange="-3 3" gear="100" joint="slider_x" name="act_x" />
        <motor ctrllimited="true" ctrlrange="-3 3" gear="100" joint="slider_y" name="act_y" />
    </actuator>
</mujoco>